Workbook

Sheet Plan
A1: Campagne de tests — plan des lancements
A2: 1 lancement = 1 objet x 1 detecteur x toutes les distances x N essais. Coche 'Statut' quand c'est fait.
A4: # | B4: Objet | C4: Detecteur | D4: Distances | E4: N | F4: Orientation a varier | G4: Commande | H4: Statut
A5: 1 | B5: orange_cube | C5: hsv | D5: proche mi loin | E5: 10 | F5: yaw (cube ~symetrique) | G5: python scripts/experiment_campaign.py --target orange_cube --detector hsv --n-per-position 10 --positions proche mi loin
A6: 2 | B6: purple_cylinder | C6: hsv | D6: proche mi loin | E6: 10 | F6: debout ET couche (~5/5 par distance) | G6: python scripts/experiment_campaign.py --target purple_cylinder --detector hsv --n-per-position 10 --positions proche mi loin
A7: 3 | B7: light_blue_ball | C7: hsv | D7: proche mi loin | E7: 10 | F7: aucune (sphere) | G7: python scripts/experiment_campaign.py --target light_blue_ball --detector hsv --n-per-position 10 --positions proche mi loin
A8: 4 | B8: blue_rectangular_box | C8: hsv | D8: proche mi loin | E8: 10 | F8: a plat: yaw + face dessous | G8: python scripts/experiment_campaign.py --target blue_rectangular_box --detector hsv --n-per-position 10 --positions proche mi loin
A9: 5 | B9: black_triangular_prism | C9: hsv | D9: proche mi loin | E9: 10 | F9: yaw + face dessous | G9: python scripts/experiment_campaign.py --target black_triangular_prism --detector hsv --n-per-position 10 --positions proche mi loin
A10: 6 | B10: orange_cube | C10: hf | D10: mi | E10: 10 | F10: yaw | G10: python scripts/experiment_campaign.py --target orange_cube --detector hf --n-per-position 10 --positions mi
A11: 7 | B11: black_triangular_prism | C11: hf | D11: mi | E11: 10 | F11: yaw (HF voit mieux le noir ?) | G11: python scripts/experiment_campaign.py --target black_triangular_prism --detector hf --n-per-position 10 --positions mi
A12: 8 | B12: light_blue_ball | C12: hf | D12: mi | E12: 10 | F12: aucune | G12: python scripts/experiment_campaign.py --target light_blue_ball --detector hf --n-per-position 10 --positions mi

Sheet Donnees
A1: REMPLI AUTOMATIQUEMENT par le script (donnees auto + tes reponses aux questions de fin d'essai). Garde l'Excel FERME pendant un run. Tu peux corriger une cellule JAUNE a la main. La Synthese se met a jour seule.
A2: objet | B2: detecteur | C2: timestamp | D2: position | E2: trial | F2: success | G2: n_attempts | H2: duration_s | I2: grasp_pose_error_mm | J2: cam2_correction_mm | K2: last_gripper_pct | L2: last_margin_pct | M2: error | N2: orientation | O2: depose_boite | P2: mode_echec | Q2: notes
A3: orange_cube | B3: hsv | C3: 2026-06-27T11:27:00 | D3: proche | E3: 1 | F3: 1 | G3: 1 | H3: 49.03 | I3: 0.12847228 | J3: 1.7290147 | K3: 10.796221 | L3: 5.7962213 | O3: oui
A4: orange_cube | B4: hsv | C4: 2026-06-27T12:25:45 | D4: proche | E4: 1 | F4: 1 | G4: 1 | H4: 47.72 | I4: 0.21139456 | J4: 8.7080764 | K4: 11.538462 | L4: 6.5384615 | O4: oui
A5: orange_cube | B5: hsv | C5: 2026-06-27T12:30:22 | D5: proche | E5: 1 | F5: 1 | G5: 1 | H5: 51.44 | I5: 0.23439675 | J5: 21.281226 | K5: 11.066127 | L5: 6.0661269 | O5: oui | Q5: E7 - cam2 KO mais réussi
A6: orange_cube | B6: hsv | C6: 2026-06-27T12:34:02 | D6: proche | E6: 1 | F6: 1 | G6: 1 | H6: 48.79 | I6: 0.44037421 | J6: 12.96486 | K6: 11.133603 | L6: 6.1336032 | O6: oui
A7: orange_cube | B7: hsv | C7: 2026-06-27T12:35:16 | D7: proche | E7: 1 | F7: 0 | G7: 2 | H7: 73.4 | I7: 0.28955553 | K7: 6.34278 | L7: 1.34278 | O7: non | Q7: cam2 KO - stéréo E1
A8: orange_cube | B8: hsv | C8: 2026-06-27T12:37:23 | D8: proche | E8: 1 | F8: 1 | G8: 1 | H8: 48.68 | I8: 0.11557899 | J8: 8.0093727 | K8: 10.728745 | L8: 5.7287449 | O8: oui
A9: orange_cube | B9: hsv | C9: 2026-06-27T12:38:20 | D9: proche | E9: 1 | F9: 1 | G9: 1 | H9: 45.56 | I9: 0.3338379 | J9: 17.337712 | K9: 11.808367 | L9: 6.8083671 | O9: oui
A10: orange_cube | B10: hsv | C10: 2026-06-27T12:39:22 | D10: proche | E10: 1 | F10: 1 | G10: 2 | H10: 60.69 | I10: 0.22470927 | K10: 12.213225 | L10: 7.2132254 | O10: oui | Q10: E5 sur premiere tentative
A11: orange_cube | B11: hsv | C11: 2026-06-27T12:41:26 | D11: proche | E11: 1 | F11: 1 | G11: 1 | H11: 47.47 | I11: 0.29395737 | J11: 8.9361245 | K11: 11.336032 | L11: 6.3360324 | O11: oui
A12: orange_cube | B12: hsv | C12: 2026-06-27T12:42:56 | D12: proche | E12: 1 | F12: 1 | G12: 1 | H12: 46.93 | I12: 0.21608889 | J12: 16.725907 | K12: 10.728745 | L12: 5.7287449 | O12: oui | Q12: Failli laché dû à l'orientation du cube
A13: orange_cube | B13: hsv | C13: 2026-06-27T14:41:23 | D13: mi | E13: 1 | F13: 1 | G13: 1 | H13: 53.3 | I13: 1.3045628 | J13: 4.4007057 | K13: 12.955466 | L13: 7.9554656 | O13: oui
A14: orange_cube | B14: hsv | C14: 2026-06-27T14:42:36 | D14: mi | E14: 1 | F14: 0 | G14: 2 | H14: 49.68 | I14: 5.0625247 | J14: 16.811996 | K14: 5.2631579 | L14: 0.26315789 | O14: non | P14: E5 | Q14: Dessus mais l'orientation a fait que
A15: orange_cube | B15: hsv | C15: 2026-06-27T14:45:27 | D15: mi | E15: 1 | F15: 0 | G15: 2 | H15: 51.7 | I15: 7.591796 | J15: 18.808193 | K15: 5.2631579 | L15: 0.26315789 | O15: non | P15: E1 | Q15: Devant l'objet
A16: orange_cube | B16: hsv | C16: 2026-06-27T14:59:30 | D16: mi | E16: 1 | F16: 1 | G16: 1 | H16: 49.08 | I16: 1.9694443 | J16: 12.727128 | K16: 12.483131 | L16: 7.4831309 | O16: oui
A17: orange_cube | B17: hsv | C17: 2026-06-27T15:00:59 | D17: mi | E17: 1 | F17: 1 | G17: 1 | H17: 57.95 | I17: 0.9222069 | K17: 14.439946 | L17: 9.439946 | O17: oui
A18: orange_cube | B18: hsv | C18: 2026-06-27T15:02:07 | D18: mi | E18: 1 | F18: 1 | G18: 1 | H18: 50.18 | I18: 0.40607595 | J18: 14.708002 | K18: 20.377868 | L18: 15.377868 | O18: non | P18: E4 | Q18: saisi sur tranche, pas bien tenu à la remontée, continuer en passant l'avoir saisi
A19: orange_cube | B19: hsv | C19: 2026-06-27T15:12:22 | D19: mi | E19: 1 | F19: 1 | G19: 1 | H19: 50.33 | I19: 0.49946835 | J19: 19.69032 | K19: 10.593792 | L19: 5.5937922 | O19: oui
A20: orange_cube | B20: hsv | C20: 2026-06-27T15:16:11 | D20: mi | E20: 1 | F20: 0 | G20: 2 | H20: 50.79 | I20: 7.0199862 | J20: 12.403423 | K20: 5.0607287 | L20: 0.060728745 | O20: non | P20: E1
A21: orange_cube | B21: hsv | C21: 2026-06-27T15:30:18 | D21: mi | E21: 1 | F21: 0 | G21: 0 | H21: 8.22 | O21: non | P21: E2 | Q21: mauvaise stéréo
A22: orange_cube | B22: hsv | C22: 2026-06-27T15:34:48 | D22: mi | E22: 1 | F22: 1 | G22: 1 | H22: 49.32 | I22: 1.6615324 | J22: 8.2129819 | K22: 12.550607 | L22: 7.5506073 | O22: oui
A23: orange_cube | B23: hsv | C23: 2026-06-27T15:37:15 | D23: loin | E23: 1 | F23: 1 | G23: 1 | H23: 48.59 | I23: 1.1015189 | J23: 5.1607589 | K23: 13.360324 | L23: 8.3603239 | O23: oui
A24: orange_cube | B24: hsv | C24: 2026-06-27T15:38:14 | D24: loin | E24: 1 | F24: 1 | G24: 2 | H24: 58.78 | I24: 0.27574603 | J24: 29.075475 | K24: 10.728745 | L24: 5.7287449 | O24: oui | Q24: objet à glisser en premiere tentative
A25: orange_cube | B25: hsv | C25: 2026-06-27T16:01:04 | D25: loin | E25: 1 | F25: 1 | G25: 1 | H25: 47.74 | I25: 6.5938015 | J25: 26.247896 | K25: 10.728745 | L25: 5.7287449 | O25: oui
A26: orange_cube | B26: hsv | C26: 2026-06-27T16:02:32 | D26: loin | E26: 1 | F26: 0 | G26: 0 | H26: 9.73 | O26: non | P26: E2 | Q26: détecté trop loin par la stéréo, cam1 a exagéré
A27: orange_cube | B27: hsv | C27: 2026-06-27T16:08:25 | D27: loin | E27: 1 | F27: 1 | G27: 1 | H27: 51.93 | I27: 4.6799977 | J27: 20.505526 | K27: 10.593792 | L27: 5.5937922 | O27: oui
A28: orange_cube | B28: hsv | C28: 2026-06-27T16:14:35 | D28: loin | E28: 1 | F28: 0 | G28: 2 | H28: 70.97 | I28: 2.473592 | J28: 32.480495 | K28: 5.3306343 | L28: 0.33063428 | O28: non | P28: E1 | Q28: objet qui a glisser et aussi pas assez bien positionné dessus
A29: orange_cube | B29: hsv | C29: 2026-06-27T16:20:30 | D29: loin | E29: 1 | F29: 0 | G29: 0 | H29: 5.4 | O29: non | P29: E2 | Q29: accessible mais mauvaise stéréo
A30: orange_cube | B30: hsv | C30: 2026-06-27T16:31:45 | D30: loin | E30: 1 | F30: 1 | G30: 1 | H30: 46.75 | I30: 4.8602834 | J30: 25.664825 | K30: 10.728745 | L30: 5.7287449 | O30: oui
A31: orange_cube | B31: hsv | C31: 2026-06-27T16:32:36 | D31: loin | E31: 1 | F31: 0 | G31: 2 | H31: 56.52 | I31: 0.69896214 | J31: 26.988409 | K31: 5.3306343 | L31: 0.33063428 | O31: non | P31: E3 | Q31: objet plus loin que détecté
A32: orange_cube | B32: hsv | C32: 2026-06-27T16:34:24 | D32: loin | E32: 1 | F32: 0 | G32: 2 | H32: 60.42 | I32: 4.567864 | J32: 33.259113 | K32: 5.1282051 | L32: 0.12820513 | O32: non | P32: E3 | Q32: mal positionné pour saisir
A33: orange_cube | B33: hf | C33: 2026-06-27T16:59:55 | D33: proche | E33: 1 | F33: 1 | G33: 1 | H33: 60.29 | I33: 0.11867199 | J33: 4.6285043 | K33: 10.391363 | L33: 5.391363 | O33: oui
A34: orange_cube | B34: hf | C34: 2026-06-27T17:01:06 | D34: proche | E34: 1 | F34: 1 | G34: 1 | H34: 58.28 | I34: 0.11405628 | J34: 15.94499 | K34: 10.323887 | L34: 5.3238866 | O34: oui
A35: orange_cube | B35: hf | C35: 2026-06-27T17:02:14 | D35: proche | E35: 1 | F35: 1 | G35: 1 | H35: 57.75 | I35: 0.19140975 | J35: 22.165518 | K35: 10.593792 | L35: 5.5937922 | O35: oui
A36: orange_cube | B36: hf | C36: 2026-06-27T17:03:22 | D36: proche | E36: 1 | F36: 1 | G36: 1 | H36: 59.53 | I36: 0.24924098 | J36: 7.2950771 | K36: 10.796221 | L36: 5.7962213 | O36: oui
A37: orange_cube | B37: hf | C37: 2026-06-27T17:04:28 | D37: proche | E37: 1 | F37: 1 | G37: 2 | H37: 78.96 | I37: 0.44271345 | J37: 16.837993 | K37: 10.99865 | L37: 5.9986505 | O37: oui | Q37: premiere tentative raté dû à l'orientation de l'l'objet, saisi sur la tranche et glisser entre les pinces
A38: orange_cube | B38: hf | C38: 2026-06-27T17:06:44 | D38: proche | E38: 1 | F38: 1 | G38: 2 | H38: 71.22 | I38: 0.3869769 | J38: 29.358993 | K38: 11.336032 | L38: 6.3360324 | O38: oui | Q38: glisser entre les pinces, mauvaise prise sur premiere tentative
A39: orange_cube | B39: hf | C39: 2026-06-27T17:08:44 | D39: proche | E39: 1 | F39: 1 | G39: 2 | H39: 82.02 | I39: 0.41481158 | J39: 22.054361 | K39: 10.99865 | L39: 5.9986505 | O39: oui | Q39: glisser entre les pinces, saisi sur tranche premiere tentative
A40: orange_cube | B40: hf | C40: 2026-06-27T17:10:55 | D40: proche | E40: 1 | F40: 1 | G40: 1 | H40: 59.37 | I40: 0.16361278 | J40: 9.0892146 | K40: 16.126856 | L40: 11.126856 | O40: oui | Q40: saisi sur tranche parfaite
...

Sheet Synthese
A1: Synthese (auto)
A2: Se calcule a partir de l'onglet Donnees. Vide tant qu'il n'y a pas d'essais.
A4: Taux de reussite — tenue apres levee (HSV)
A5: Objet | B5: proche | C5: mi | D5: loin | E5: global
A6: orange_cube | B6: =IF(COUNTIFS(Donnees!$A:$A,$A6,Donnees!$D:$D,B5,Donnees!$B:$B,"hsv")=0,"",COUNTIFS(Donnees!$A:$A,$A6,Donnees!$D:$D,B5,Donnees!$B:$B,"hsv",Donnees!$F:$F,1)/COUNTIFS(Donnees!$A:$A,$A6,Donnees!$D:$D,B5,Donnees!$B:$B,"hsv")) -> 0.9 | C6: =IF(COUNTIFS(Donnees!$A:$A,$A6,Donnees!$D:$D,C5,Donnees!$B:$B,"hsv")=0,"",COUNTIFS(Donnees!$A:$A,$A6,Donnees!$D:$D,C5,Donnees!$B:$B,"hsv",Donnees!$F:$F,1)/COUNTIFS(Donnees!$A:$A,$A6,Donnees!$D:$D,C5,Donnees!$B:$B,"hsv")) -> 0.6 | D6: =IF(COUNTIFS(Donnees!$A:$A,$A6,Donnees!$D:$D,D5,Donnees!$B:$B,"hsv")=0,"",COUNTIFS(Donnees!$A:$A,$A6,Donnees!$D:$D,D5,Donnees!$B:$B,"hsv",Donnees!$F:$F,1)/COUNTIFS(Donnees!$A:$A,$A6,Donnees!$D:$D,D5,Donnees!$B:$B,"hsv")) -> 0.5 | E6: =IF(COUNTIFS(Donnees!$A:$A,$A6,Donnees!$B:$B,"hsv")=0,"",COUNTIFS(Donnees!$A:$A,$A6,Donnees!$B:$B,"hsv",Donnees!$F:$F,1)/COUNTIFS(Donnees!$A:$A,$A6,Donnees!$B:$B,"hsv")) -> 0.66666667
A7: purple_cylinder | B7: =IF(COUNTIFS(Donnees!$A:$A,$A7,Donnees!$D:$D,B5,Donnees!$B:$B,"hsv")=0,"",COUNTIFS(Donnees!$A:$A,$A7,Donnees!$D:$D,B5,Donnees!$B:$B,"hsv",Donnees!$F:$F,1)/COUNTIFS(Donnees!$A:$A,$A7,Donnees!$D:$D,B5,Donnees!$B:$B,"hsv")) -> 1 | C7: =IF(COUNTIFS(Donnees!$A:$A,$A7,Donnees!$D:$D,C5,Donnees!$B:$B,"hsv")=0,"",COUNTIFS(Donnees!$A:$A,$A7,Donnees!$D:$D,C5,Donnees!$B:$B,"hsv",Donnees!$F:$F,1)/COUNTIFS(Donnees!$A:$A,$A7,Donnees!$D:$D,C5,Donnees!$B:$B,"hsv")) -> 0.33333333 | D7: =IF(COUNTIFS(Donnees!$A:$A,$A7,Donnees!$D:$D,D5,Donnees!$B:$B,"hsv")=0,"",COUNTIFS(Donnees!$A:$A,$A7,Donnees!$D:$D,D5,Donnees!$B:$B,"hsv",Donnees!$F:$F,1)/COUNTIFS(Donnees!$A:$A,$A7,Donnees!$D:$D,D5,Donnees!$B:$B,"hsv")) -> 0.66666667 | E7: =IF(COUNTIFS(Donnees!$A:$A,$A7,Donnees!$B:$B,"hsv")=0,"",COUNTIFS(Donnees!$A:$A,$A7,Donnees!$B:$B,"hsv",Donnees!$F:$F,1)/COUNTIFS(Donnees!$A:$A,$A7,Donnees!$B:$B,"hsv")) -> 0.66666667
A8: light_blue_ball | B8: =IF(COUNTIFS(Donnees!$A:$A,$A8,Donnees!$D:$D,B5,Donnees!$B:$B,"hsv")=0,"",COUNTIFS(Donnees!$A:$A,$A8,Donnees!$D:$D,B5,Donnees!$B:$B,"hsv",Donnees!$F:$F,1)/COUNTIFS(Donnees!$A:$A,$A8,Donnees!$D:$D,B5,Donnees!$B:$B,"hsv")) | C8: =IF(COUNTIFS(Donnees!$A:$A,$A8,Donnees!$D:$D,C5,Donnees!$B:$B,"hsv")=0,"",COUNTIFS(Donnees!$A:$A,$A8,Donnees!$D:$D,C5,Donnees!$B:$B,"hsv",Donnees!$F:$F,1)/COUNTIFS(Donnees!$A:$A,$A8,Donnees!$D:$D,C5,Donnees!$B:$B,"hsv")) | D8: =IF(COUNTIFS(Donnees!$A:$A,$A8,Donnees!$D:$D,D5,Donnees!$B:$B,"hsv")=0,"",COUNTIFS(Donnees!$A:$A,$A8,Donnees!$D:$D,D5,Donnees!$B:$B,"hsv",Donnees!$F:$F,1)/COUNTIFS(Donnees!$A:$A,$A8,Donnees!$D:$D,D5,Donnees!$B:$B,"hsv")) | E8: =IF(COUNTIFS(Donnees!$A:$A,$A8,Donnees!$B:$B,"hsv")=0,"",COUNTIFS(Donnees!$A:$A,$A8,Donnees!$B:$B,"hsv",Donnees!$F:$F,1)/COUNTIFS(Donnees!$A:$A,$A8,Donnees!$B:$B,"hsv"))
A9: blue_rectangular_box | B9: =IF(COUNTIFS(Donnees!$A:$A,$A9,Donnees!$D:$D,B5,Donnees!$B:$B,"hsv")=0,"",COUNTIFS(Donnees!$A:$A,$A9,Donnees!$D:$D,B5,Donnees!$B:$B,"hsv",Donnees!$F:$F,1)/COUNTIFS(Donnees!$A:$A,$A9,Donnees!$D:$D,B5,Donnees!$B:$B,"hsv")) | C9: =IF(COUNTIFS(Donnees!$A:$A,$A9,Donnees!$D:$D,C5,Donnees!$B:$B,"hsv")=0,"",COUNTIFS(Donnees!$A:$A,$A9,Donnees!$D:$D,C5,Donnees!$B:$B,"hsv",Donnees!$F:$F,1)/COUNTIFS(Donnees!$A:$A,$A9,Donnees!$D:$D,C5,Donnees!$B:$B,"hsv")) | D9: =IF(COUNTIFS(Donnees!$A:$A,$A9,Donnees!$D:$D,D5,Donnees!$B:$B,"hsv")=0,"",COUNTIFS(Donnees!$A:$A,$A9,Donnees!$D:$D,D5,Donnees!$B:$B,"hsv",Donnees!$F:$F,1)/COUNTIFS(Donnees!$A:$A,$A9,Donnees!$D:$D,D5,Donnees!$B:$B,"hsv")) | E9: =IF(COUNTIFS(Donnees!$A:$A,$A9,Donnees!$B:$B,"hsv")=0,"",COUNTIFS(Donnees!$A:$A,$A9,Donnees!$B:$B,"hsv",Donnees!$F:$F,1)/COUNTIFS(Donnees!$A:$A,$A9,Donnees!$B:$B,"hsv"))
A10: black_triangular_prism | B10: =IF(COUNTIFS(Donnees!$A:$A,$A10,Donnees!$D:$D,B5,Donnees!$B:$B,"hsv")=0,"",COUNTIFS(Donnees!$A:$A,$A10,Donnees!$D:$D,B5,Donnees!$B:$B,"hsv",Donnees!$F:$F,1)/COUNTIFS(Donnees!$A:$A,$A10,Donnees!$D:$D,B5,Donnees!$B:$B,"hsv")) | C10: =IF(COUNTIFS(Donnees!$A:$A,$A10,Donnees!$D:$D,C5,Donnees!$B:$B,"hsv")=0,"",COUNTIFS(Donnees!$A:$A,$A10,Donnees!$D:$D,C5,Donnees!$B:$B,"hsv",Donnees!$F:$F,1)/COUNTIFS(Donnees!$A:$A,$A10,Donnees!$D:$D,C5,Donnees!$B:$B,"hsv")) | D10: =IF(COUNTIFS(Donnees!$A:$A,$A10,Donnees!$D:$D,D5,Donnees!$B:$B,"hsv")=0,"",COUNTIFS(Donnees!$A:$A,$A10,Donnees!$D:$D,D5,Donnees!$B:$B,"hsv",Donnees!$F:$F,1)/COUNTIFS(Donnees!$A:$A,$A10,Donnees!$D:$D,D5,Donnees!$B:$B,"hsv")) | E10: =IF(COUNTIFS(Donnees!$A:$A,$A10,Donnees!$B:$B,"hsv")=0,"",COUNTIFS(Donnees!$A:$A,$A10,Donnees!$B:$B,"hsv",Donnees!$F:$F,1)/COUNTIFS(Donnees!$A:$A,$A10,Donnees!$B:$B,"hsv"))
A13: Nombre d'essais (HSV)
A14: Objet | B14: proche | C14: mi | D14: loin | E14: global
A15: orange_cube | B15: =IF(COUNTIFS(Donnees!$A:$A,$A15,Donnees!$D:$D,B14,Donnees!$B:$B,"hsv")=0,"",COUNTIFS(Donnees!$A:$A,$A15,Donnees!$D:$D,B14,Donnees!$B:$B,"hsv")) -> 10 | C15: =IF(COUNTIFS(Donnees!$A:$A,$A15,Donnees!$D:$D,C14,Donnees!$B:$B,"hsv")=0,"",COUNTIFS(Donnees!$A:$A,$A15,Donnees!$D:$D,C14,Donnees!$B:$B,"hsv")) -> 10 | D15: =IF(COUNTIFS(Donnees!$A:$A,$A15,Donnees!$D:$D,D14,Donnees!$B:$B,"hsv")=0,"",COUNTIFS(Donnees!$A:$A,$A15,Donnees!$D:$D,D14,Donnees!$B:$B,"hsv")) -> 10 | E15: =IF(COUNTIFS(Donnees!$A:$A,$A15,Donnees!$B:$B,"hsv")=0,"",COUNTIFS(Donnees!$A:$A,$A15,Donnees!$B:$B,"hsv")) -> 30
A16: purple_cylinder | B16: =IF(COUNTIFS(Donnees!$A:$A,$A16,Donnees!$D:$D,B14,Donnees!$B:$B,"hsv")=0,"",COUNTIFS(Donnees!$A:$A,$A16,Donnees!$D:$D,B14,Donnees!$B:$B,"hsv")) -> 3 | C16: =IF(COUNTIFS(Donnees!$A:$A,$A16,Donnees!$D:$D,C14,Donnees!$B:$B,"hsv")=0,"",COUNTIFS(Donnees!$A:$A,$A16,Donnees!$D:$D,C14,Donnees!$B:$B,"hsv")) -> 3 | D16: =IF(COUNTIFS(Donnees!$A:$A,$A16,Donnees!$D:$D,D14,Donnees!$B:$B,"hsv")=0,"",COUNTIFS(Donnees!$A:$A,$A16,Donnees!$D:$D,D14,Donnees!$B:$B,"hsv")) -> 3 | E16: =IF(COUNTIFS(Donnees!$A:$A,$A16,Donnees!$B:$B,"hsv")=0,"",COUNTIFS(Donnees!$A:$A,$A16,Donnees!$B:$B,"hsv")) -> 9
A17: light_blue_ball | B17: =IF(COUNTIFS(Donnees!$A:$A,$A17,Donnees!$D:$D,B14,Donnees!$B:$B,"hsv")=0,"",COUNTIFS(Donnees!$A:$A,$A17,Donnees!$D:$D,B14,Donnees!$B:$B,"hsv")) | C17: =IF(COUNTIFS(Donnees!$A:$A,$A17,Donnees!$D:$D,C14,Donnees!$B:$B,"hsv")=0,"",COUNTIFS(Donnees!$A:$A,$A17,Donnees!$D:$D,C14,Donnees!$B:$B,"hsv")) | D17: =IF(COUNTIFS(Donnees!$A:$A,$A17,Donnees!$D:$D,D14,Donnees!$B:$B,"hsv")=0,"",COUNTIFS(Donnees!$A:$A,$A17,Donnees!$D:$D,D14,Donnees!$B:$B,"hsv")) | E17: =IF(COUNTIFS(Donnees!$A:$A,$A17,Donnees!$B:$B,"hsv")=0,"",COUNTIFS(Donnees!$A:$A,$A17,Donnees!$B:$B,"hsv"))
A18: blue_rectangular_box | B18: =IF(COUNTIFS(Donnees!$A:$A,$A18,Donnees!$D:$D,B14,Donnees!$B:$B,"hsv")=0,"",COUNTIFS(Donnees!$A:$A,$A18,Donnees!$D:$D,B14,Donnees!$B:$B,"hsv")) | C18: =IF(COUNTIFS(Donnees!$A:$A,$A18,Donnees!$D:$D,C14,Donnees!$B:$B,"hsv")=0,"",COUNTIFS(Donnees!$A:$A,$A18,Donnees!$D:$D,C14,Donnees!$B:$B,"hsv")) | D18: =IF(COUNTIFS(Donnees!$A:$A,$A18,Donnees!$D:$D,D14,Donnees!$B:$B,"hsv")=0,"",COUNTIFS(Donnees!$A:$A,$A18,Donnees!$D:$D,D14,Donnees!$B:$B,"hsv")) | E18: =IF(COUNTIFS(Donnees!$A:$A,$A18,Donnees!$B:$B,"hsv")=0,"",COUNTIFS(Donnees!$A:$A,$A18,Donnees!$B:$B,"hsv"))
A19: black_triangular_prism | B19: =IF(COUNTIFS(Donnees!$A:$A,$A19,Donnees!$D:$D,B14,Donnees!$B:$B,"hsv")=0,"",COUNTIFS(Donnees!$A:$A,$A19,Donnees!$D:$D,B14,Donnees!$B:$B,"hsv")) | C19: =IF(COUNTIFS(Donnees!$A:$A,$A19,Donnees!$D:$D,C14,Donnees!$B:$B,"hsv")=0,"",COUNTIFS(Donnees!$A:$A,$A19,Donnees!$D:$D,C14,Donnees!$B:$B,"hsv")) | D19: =IF(COUNTIFS(Donnees!$A:$A,$A19,Donnees!$D:$D,D14,Donnees!$B:$B,"hsv")=0,"",COUNTIFS(Donnees!$A:$A,$A19,Donnees!$D:$D,D14,Donnees!$B:$B,"hsv")) | E19: =IF(COUNTIFS(Donnees!$A:$A,$A19,Donnees!$B:$B,"hsv")=0,"",COUNTIFS(Donnees!$A:$A,$A19,Donnees!$B:$B,"hsv"))
A22: Modes d'echec (tous essais)
A23: E1 | B23: E2 | C23: E3 | D23: E4 | E23: E5 | F23: E6 | G23: E7
A24: =COUNTIF(Donnees!$P:$P,"E1") -> 6 | B24: =COUNTIF(Donnees!$P:$P,"E2") -> 8 | C24: =COUNTIF(Donnees!$P:$P,"E3") -> 5 | D24: =COUNTIF(Donnees!$P:$P,"E4") -> 1 | E24: =COUNTIF(Donnees!$P:$P,"E5") -> 1 | F24: =COUNTIF(Donnees!$P:$P,"E6") -> 0 | G24: =COUNTIF(Donnees!$P:$P,"E7") -> 0
A25: perception | B25: IK injoignable | C25: fermeture a vide | D25: perte a la levee | E25: saisie orientation | F25: rate du depot | G25: materiel
A27: Precision moyenne (tous essais)
A28: Erreur de pose atteinte (mm) | C28: =IFERROR(AVERAGE(Donnees!I:I),"") -> 2.0422794
A29: Correction cam_2 (mm) | C29: =IFERROR(AVERAGE(Donnees!J:J),"") -> 13.279048
A31: Taux de reussite — HF a mi
A32: Objet | B32: mi
A33: orange_cube | B33: =IF(COUNTIFS(Donnees!$A:$A,$A33,Donnees!$D:$D,"mi",Donnees!$B:$B,"hf")=0,"",COUNTIFS(Donnees!$A:$A,$A33,Donnees!$D:$D,"mi",Donnees!$B:$B,"hf",Donnees!$F:$F,1)/COUNTIFS(Donnees!$A:$A,$A33,Donnees!$D:$D,"mi",Donnees!$B:$B,"hf")) -> 0.7
A34: black_triangular_prism | B34: =IF(COUNTIFS(Donnees!$A:$A,$A34,Donnees!$D:$D,"mi",Donnees!$B:$B,"hf")=0,"",COUNTIFS(Donnees!$A:$A,$A34,Donnees!$D:$D,"mi",Donnees!$B:$B,"hf",Donnees!$F:$F,1)/COUNTIFS(Donnees!$A:$A,$A34,Donnees!$D:$D,"mi",Donnees!$B:$B,"hf"))
A35: light_blue_ball | B35: =IF(COUNTIFS(Donnees!$A:$A,$A35,Donnees!$D:$D,"mi",Donnees!$B:$B,"hf")=0,"",COUNTIFS(Donnees!$A:$A,$A35,Donnees!$D:$D,"mi",Donnees!$B:$B,"hf",Donnees!$F:$F,1)/COUNTIFS(Donnees!$A:$A,$A35,Donnees!$D:$D,"mi",Donnees!$B:$B,"hf"))

Sheet Legende
A1: Legende & conventions
A3: COLONNES D'OBSERVATION (le script te les DEMANDE a chaque essai ; jaunes, modifiables a la main)
A4: orientation | B4: pose physique de l'objet : debout / couche / a plat / sur tranche / aucune. ENTREE = idem essai precedent
A5: depose_boite | B5: oui/non : l'objet est-il VRAIMENT tombe dans la boite ? ENTREE = auto (oui si saisi, non sinon). Le 'success' du script = seulement tenu apres la levee
A6: mode_echec | B6: si rate, le code E1-E7 ci-dessous. Demande seulement quand l'essai a echoue
A7: notes | B7: tout ce qui est notable (cam_2 a decroche, objet a glisse, etc.). ENTREE = rien
A9: MODES D'ECHEC
A10: E1 | B10: perception : objet mal localise ou non detecte
A11: E2 | B11: IK : aucun angle d'attaque atteignable
A12: E3 | B12: fermeture a vide : la pince se ferme sans rien attraper
A13: E4 | B13: perte a la levee : l'objet attrape retombe en montant
A14: E5 | B14: mauvaise saisie : prise sur coin/tranche a cause de l'orientation
A15: E6 | B15: rate du depot : attrape/leve mais pas depose dans la boite
A16: E7 | B16: materiel : cam_2 USB, moteur, hub, etc.
A18: COLONNES AUTOMATIQUES (remplies par le script)
A19: success | B19: 1 = objet tenu apres la levee (proxy couple/position). N'EST PAS le depot visuel -> cf depose_boite
A20: n_attempts | B20: 1 = saisi du 1er coup, 2 = il a fallu un retry. Si > 1 et echec final -> compte comme rate
A21: duration_s | B21: duree totale du cycle (sec). HF sera plus lent que HSV (OWL-ViT)
A22: grasp_pose_error_mm | B22: erreur de pose ATTEINTE = residu IK de la prise retenue (precision bras 5-DDL). Y-free
A23: cam2_correction_mm | B23: amplitude de la correction cam_2 = ecart stereo -> position raffinee (precision perception). Y-free
A25: CONVENTIONS DISTANCE
A26: proche / mi / loin | B26: vise un RAYON constant ~20 / ~30 / ~40 cm depuis la base (d = racine(x^2+y^2))
A27: varier la position | B27: deplace l'objet le long d'un ARC de ce rayon (varie le cote / l'angle), PAS seulement sur l'axe x. Tolerance ~+-2 cm sur le rayon
A29: WORKFLOW
A30: 0 | B30: garde CE classeur FERME pendant un run (sinon il est verrouille ; le script te previent)
A31: 1 | B31: lance une commande de l'onglet Plan. A CHAQUE essai le script demande : orientation / depose boite / mode echec / note (ENTREE = defaut)
A32: 2 | B32: a la fin de la commande, le script ecrit TOUT (auto + tes reponses) dans l'onglet Donnees, et aussi un CSV de secours dans outputs/experiments/
A33: 3 | B33: ouvre l'Excel : tout est rempli, la Synthese est a jour. Corrige une cellule jaune si besoin, coche 'Statut' dans Plan
